<?xml version="1.0"?>
<robot xmlns:xacro="http://www.ros.org/wiki/xacro">

    <xacro:include filename="inertial_macros.xacro"/>

    <material name="white">
        <color rgba="1 1 1 1" />
    </material>

    <material name="orange">
        <color rgba="1 0.3 0.1 1"/>
    </material>

    <material name="blue">
        <color rgba="0.2 0.2 1 1"/>
    </material>

    <material name="black">
        <color rgba="0 0 0 1"/>
    </material>

    <link name="base_link">

    </link>

    <joint name="chassis_joint" type="fixed">
        <parent link="base_link"/>
        <child link="chassis"/>  
        <origin xyz="0 0 0.034"/>
    </joint>

    <link name="chassis">
        <visual>
            <origin xyz="0.09 0 0.02" rpy="0 0 0"/>
            <geometry>
                <box size="0.23 0.214 0.040"/>
            </geometry>
            <material name="white"/>
        </visual>                                           
        <collision>
            <origin xyz="0.09 0 0.02" rpy="0 0 0"/>
            <geometry>
                <box size="0.23 0.214 0.040"/>
            </geometry>
        </collision>
        <xacro:inertial_box mass="0.5" x="0.23" y="0.214" z="0.04">
            <origin xyz="0.09 0 0.02" rpy="0 0 0"/>
        </xacro:inertial_box>
    </link>
    <!--WHEELS-->
    <!--Left-->  
     <joint name="wheel_joint_l" type="continuous">
        <parent link="base_link"/>
        <child link="wheel_l"/>  
        <origin xyz="-0.022 0.1205 0.034" rpy="-${pi/2} 0 0"/>
        <axis xyz="0 0 1"/>
    </joint>

    <link name="wheel_l">
        <visual>
            <geometry>
                <cylinder length="0.026" radius="0.034"/>
            </geometry>
            <material name="orange"/>
        </visual>                                           
        <collision>
            <geometry>
                <cylinder length="0.026" radius="0.034"/>
            </geometry>
        </collision>
        <xacro:inertial_cylinder mass="0.05" length="0.026" radius="0.034">
            <origin xyz="0 0 0" rpy="0 0 0"/>
        </xacro:inertial_cylinder>
    </link>
    <!--Left-->  
     <joint name="wheel_joint_r" type="continuous">
        <parent link="base_link"/>
        <child link="wheel_r"/>  
        <origin xyz="-0.022 -0.1205 0.034" rpy="${pi/2} 0 0"/>
        <axis xyz="0 0 -1"/>
    </joint>

    <link name="wheel_r">
        <visual>
            <geometry>
                <cylinder length="0.026" radius="0.034"/>
            </geometry>
            <material name="orange"/>
        </visual>                                           
        <collision>
            <geometry>
                <cylinder length="0.026" radius="0.034"/>
            </geometry>
        </collision>
        <xacro:inertial_cylinder mass="0.05" length="0.026" radius="0.034">
            <origin xyz="0 0 0" rpy="0 0 0"/>
        </xacro:inertial_cylinder>
    </link>
    <!-- BALL JOINT-->
    <joint name="ball_joint" type="fixed">
        <parent link="chassis"/>
        <child link="ball"/>  
        <origin xyz="0.145 0 0"/>
    </joint>

    <link name="ball">
        <visual>
            <geometry>
                <sphere radius="0.034"/>
            </geometry>
            <material name="black"/>
        </visual>
        <collision>
            <geometry>
                <sphere radius="0.034"/>
            </geometry>
            <material name="black"/>
        </collision>
        <xacro:inertial_sphere mass="0.1" radius="0.034">
            <origin xyz="0 0 0" rpy="0 0 0"/>
        </xacro:inertial_sphere>
    </link>
    <gazebo reference="ball">
        <mu1 value="0.001"/>
        <mu2 value="0.001"/>
    </gazebo>


</robot>